Workbook

Sheet Investment Log
A1: INVESTMENT LOG — Ishwarya
A2: Single source of truth. Add each investment as one new row → the category tabs update automatically. Type only in the white columns.
A4: TOTAL INVESTED (₹) | D4: TOTAL GOLD (g) | F4: RECORDS
A5: =SUM($E$8:$E$500) -> 1768750 | D5: =SUM($F$8:$F$500) -> 137.5 | F5: =COUNTA($C$8:$C$500) -> 15
A7: S.No | B7: Date | C7: Category | D7: Description / Name | E7: Amount Invested (₹) | F7: Gold (grams) | G7: Platform / Account | H7: Notes | I7: Period (auto) | J7: Cumulative (₹) (auto)
A8: =IF($C8="","",ROW()-7) -> 1 | B8: Opening | C8: Gold | D8: Existing holding (opening) | F8: 84.2 | G8: — | H8: Opening balance, pre-2025. Purchase cost not recorded. | I8: =IF(OR($B8="",ISTEXT($B8)),IF($B8="Opening","Opening",""),TEXT($B8,"mmm yyyy")) -> Opening | J8: =IF(AND($E8="",$F8=""),"",SUM($E$8:$E8)) -> 0 | L8: =IF($C8="","",COUNTIFS($C$8:$C8,$C8)) -> 1 | M8: =IF($C8="","",$C8&"|"&$L8) -> Gold|1
A9: =IF($C9="","",ROW()-7) -> 2 | B9: 45658 | C9: Gold | F9: 12.9 | G9: — | H9: Bought 12.9 g. ₹ not recorded. Day not specified. | I9: =IF(OR($B9="",ISTEXT($B9)),IF($B9="Opening","Opening",""),TEXT($B9,"mmm yyyy")) -> Jan 2025 | J9: =IF(AND($E9="",$F9=""),"",SUM($E$8:$E9)) -> 0 | L9: =IF($C9="","",COUNTIFS($C$8:$C9,$C9)) -> 2 | M9: =IF($C9="","",$C9&"|"&$L9) -> Gold|2
A10: =IF($C10="","",ROW()-7) -> 3 | B10: 45717 | C10: Gold | F10: 10.9 | G10: — | H10: Bought 10.9 g. ₹ not recorded. Day not specified. | I10: =IF(OR($B10="",ISTEXT($B10)),IF($B10="Opening","Opening",""),TEXT($B10,"mmm yyyy")) -> Mar 2025 | J10: =IF(AND($E10="",$F10=""),"",SUM($E$8:$E10)) -> 0 | L10: =IF($C10="","",COUNTIFS($C$8:$C10,$C10)) -> 3 | M10: =IF($C10="","",$C10&"|"&$L10) -> Gold|3
A11: =IF($C11="","",ROW()-7) -> 4 | B11: 45992 | C11: Real Estate | D11: PRIDE | E11: 750000 | G11: PRIDE | H11: ₹7.5L to PRIDE. Confirm nature (property?). Day not specified. | I11: =IF(OR($B11="",ISTEXT($B11)),IF($B11="Opening","Opening",""),TEXT($B11,"mmm yyyy")) -> Dec 2025 | J11: =IF(AND($E11="",$F11=""),"",SUM($E$8:$E11)) -> 750000 | L11: =IF($C11="","",COUNTIFS($C$8:$C11,$C11)) -> 1 | M11: =IF($C11="","",$C11&"|"&$L11) -> Real Estate|1
A12: =IF($C12="","",ROW()-7) -> 5 | B12: 46054 | C12: Mutual Funds | D12: Kuvera portfolio | E12: 200000 | G12: Kuvera app | H12: Day not specified. | I12: =IF(OR($B12="",ISTEXT($B12)),IF($B12="Opening","Opening",""),TEXT($B12,"mmm yyyy")) -> Feb 2026 | J12: =IF(AND($E12="",$F12=""),"",SUM($E$8:$E12)) -> 950000 | L12: =IF($C12="","",COUNTIFS($C$8:$C12,$C12)) -> 1 | M12: =IF($C12="","",$C12&"|"&$L12) -> Mutual Funds|1
A13: =IF($C13="","",ROW()-7) -> 6 | B13: 46054 | C13: Fixed Deposit | D13: ICICI FD | E13: 150000 | G13: ICICI | H13: Day not specified. Rate / tenure not recorded. | I13: =IF(OR($B13="",ISTEXT($B13)),IF($B13="Opening","Opening",""),TEXT($B13,"mmm yyyy")) -> Feb 2026 | J13: =IF(AND($E13="",$F13=""),"",SUM($E$8:$E13)) -> 1100000 | L13: =IF($C13="","",COUNTIFS($C$8:$C13,$C13)) -> 1 | M13: =IF($C13="","",$C13&"|"&$L13) -> Fixed Deposit|1
A14: =IF($C14="","",ROW()-7) -> 7 | B14: 46082 | C14: Gold | E14: 100000 | F14: 6.62 | G14: — | H14: ₹1L → 6.62 g. Day not specified. | I14: =IF(OR($B14="",ISTEXT($B14)),IF($B14="Opening","Opening",""),TEXT($B14,"mmm yyyy")) -> Mar 2026 | J14: =IF(AND($E14="",$F14=""),"",SUM($E$8:$E14)) -> 1200000 | L14: =IF($C14="","",COUNTIFS($C$8:$C14,$C14)) -> 4 | M14: =IF($C14="","",$C14&"|"&$L14) -> Gold|4
A15: =IF($C15="","",ROW()-7) -> 8 | B15: 46113 | C15: Gold | E15: 100000 | F15: 6.58 | G15: — | H15: ₹1L → 6.58 g. Day not specified. | I15: =IF(OR($B15="",ISTEXT($B15)),IF($B15="Opening","Opening",""),TEXT($B15,"mmm yyyy")) -> Apr 2026 | J15: =IF(AND($E15="",$F15=""),"",SUM($E$8:$E15)) -> 1300000 | L15: =IF($C15="","",COUNTIFS($C$8:$C15,$C15)) -> 5 | M15: =IF($C15="","",$C15&"|"&$L15) -> Gold|5
A16: =IF($C16="","",ROW()-7) -> 9 | B16: 46143 | C16: Fixed Deposit | D16: FD | E16: 50000 | G16: — | H16: Day / bank not specified. | I16: =IF(OR($B16="",ISTEXT($B16)),IF($B16="Opening","Opening",""),TEXT($B16,"mmm yyyy")) -> May 2026 | J16: =IF(AND($E16="",$F16=""),"",SUM($E$8:$E16)) -> 1350000 | L16: =IF($C16="","",COUNTIFS($C$8:$C16,$C16)) -> 2 | M16: =IF($C16="","",$C16&"|"&$L16) -> Fixed Deposit|2
A17: =IF($C17="","",ROW()-7) -> 10 | B17: 46174 | C17: Gold | E17: 120000 | F17: 10 | G17: — | H17: ₹1.2L → 10 g. Day not specified. | I17: =IF(OR($B17="",ISTEXT($B17)),IF($B17="Opening","Opening",""),TEXT($B17,"mmm yyyy")) -> Jun 2026 | J17: =IF(AND($E17="",$F17=""),"",SUM($E$8:$E17)) -> 1470000 | L17: =IF($C17="","",COUNTIFS($C$8:$C17,$C17)) -> 6 | M17: =IF($C17="","",$C17&"|"&$L17) -> Gold|6
A18: =IF($C18="","",ROW()-7) -> 11 | B18: 46204 | C18: Stocks | D18: Sanskrut Shares | E18: 20000 | G18: — | H18: Day not specified. (Unlisted / private shares?) | I18: =IF(OR($B18="",ISTEXT($B18)),IF($B18="Opening","Opening",""),TEXT($B18,"mmm yyyy")) -> Jul 2026 | J18: =IF(AND($E18="",$F18=""),"",SUM($E$8:$E18)) -> 1490000 | L18: =IF($C18="","",COUNTIFS($C$8:$C18,$C18)) -> 1 | M18: =IF($C18="","",$C18&"|"&$L18) -> Stocks|1
A19: =IF($C19="","",ROW()-7) -> 12 | B19: 46237 | C19: Stocks | D19: NSE Stocks | E19: 98750 | G19: — | I19: =IF(OR($B19="",ISTEXT($B19)),IF($B19="Opening","Opening",""),TEXT($B19,"mmm yyyy")) -> Aug 2026 | J19: =IF(AND($E19="",$F19=""),"",SUM($E$8:$E19)) -> 1588750 | L19: =IF($C19="","",COUNTIFS($C$8:$C19,$C19)) -> 2 | M19: =IF($C19="","",$C19&"|"&$L19) -> Stocks|2
A20: =IF($C20="","",ROW()-7) -> 13 | B20: 46237 | C20: IPO | D20: Manipal Health | E20: 30000 | G20: — | H20: IPO. Exact date assumed = 3 Aug; confirm. | I20: =IF(OR($B20="",ISTEXT($B20)),IF($B20="Opening","Opening",""),TEXT($B20,"mmm yyyy")) -> Aug 2026 | J20: =IF(AND($E20="",$F20=""),"",SUM($E$8:$E20)) -> 1618750 | L20: =IF($C20="","",COUNTIFS($C$8:$C20,$C20)) -> 1 | M20: =IF($C20="","",$C20&"|"&$L20) -> IPO|1
A21: =IF($C21="","",ROW()-7) -> 14 | B21: 46237 | C21: Gold | E21: 100000 | F21: 6.3 | G21: — | H21: ₹1L → 6.3 g. Date assumed = 3 Aug. | I21: =IF(OR($B21="",ISTEXT($B21)),IF($B21="Opening","Opening",""),TEXT($B21,"mmm yyyy")) -> Aug 2026 | J21: =IF(AND($E21="",$F21=""),"",SUM($E$8:$E21)) -> 1718750 | L21: =IF($C21="","",COUNTIFS($C$8:$C21,$C21)) -> 7 | M21: =IF($C21="","",$C21&"|"&$L21) -> Gold|7
A22: =IF($C22="","",ROW()-7) -> 15 | B22: 46265 | C22: Fixed Deposit | D22: ICICI FD | E22: 50000 | G22: ICICI | H22: 3.5 years @ 6.5% interest. | I22: =IF(OR($B22="",ISTEXT($B22)),IF($B22="Opening","Opening",""),TEXT($B22,"mmm yyyy")) -> Aug 2026 | J22: =IF(AND($E22="",$F22=""),"",SUM($E$8:$E22)) -> 1768750 | L22: =IF($C22="","",COUNTIFS($C$8:$C22,$C22)) -> 3 | M22: =IF($C22="","",$C22&"|"&$L22) -> Fixed Deposit|3
A23: =IF($C23="","",ROW()-7) | I23: =IF(OR($B23="",ISTEXT($B23)),IF($B23="Opening","Opening",""),TEXT($B23,"mmm yyyy")) | J23: =IF(AND($E23="",$F23=""),"",SUM($E$8:$E23)) | L23: =IF($C23="","",COUNTIFS($C$8:$C23,$C23)) | M23: =IF($C23="","",$C23&"|"&$L23)
A24: =IF($C24="","",ROW()-7) | I24: =IF(OR($B24="",ISTEXT($B24)),IF($B24="Opening","Opening",""),TEXT($B24,"mmm yyyy")) | J24: =IF(AND($E24="",$F24=""),"",SUM($E$8:$E24)) | L24: =IF($C24="","",COUNTIFS($C$8:$C24,$C24)) | M24: =IF($C24="","",$C24&"|"&$L24)
A25: =IF($C25="","",ROW()-7) | I25: =IF(OR($B25="",ISTEXT($B25)),IF($B25="Opening","Opening",""),TEXT($B25,"mmm yyyy")) | J25: =IF(AND($E25="",$F25=""),"",SUM($E$8:$E25)) | L25: =IF($C25="","",COUNTIFS($C$8:$C25,$C25)) | M25: =IF($C25="","",$C25&"|"&$L25)
A26: =IF($C26="","",ROW()-7) | I26: =IF(OR($B26="",ISTEXT($B26)),IF($B26="Opening","Opening",""),TEXT($B26,"mmm yyyy")) | J26: =IF(AND($E26="",$F26=""),"",SUM($E$8:$E26)) | L26: =IF($C26="","",COUNTIFS($C$8:$C26,$C26)) | M26: =IF($C26="","",$C26&"|"&$L26)
A27: =IF($C27="","",ROW()-7) | I27: =IF(OR($B27="",ISTEXT($B27)),IF($B27="Opening","Opening",""),TEXT($B27,"mmm yyyy")) | J27: =IF(AND($E27="",$F27=""),"",SUM($E$8:$E27)) | L27: =IF($C27="","",COUNTIFS($C$8:$C27,$C27)) | M27: =IF($C27="","",$C27&"|"&$L27)
A28: =IF($C28="","",ROW()-7) | I28: =IF(OR($B28="",ISTEXT($B28)),IF($B28="Opening","Opening",""),TEXT($B28,"mmm yyyy")) | J28: =IF(AND($E28="",$F28=""),"",SUM($E$8:$E28)) | L28: =IF($C28="","",COUNTIFS($C$8:$C28,$C28)) | M28: =IF($C28="","",$C28&"|"&$L28)
A29: =IF($C29="","",ROW()-7) | I29: =IF(OR($B29="",ISTEXT($B29)),IF($B29="Opening","Opening",""),TEXT($B29,"mmm yyyy")) | J29: =IF(AND($E29="",$F29=""),"",SUM($E$8:$E29)) | L29: =IF($C29="","",COUNTIFS($C$8:$C29,$C29)) | M29: =IF($C29="","",$C29&"|"&$L29)
A30: =IF($C30="","",ROW()-7) | I30: =IF(OR($B30="",ISTEXT($B30)),IF($B30="Opening","Opening",""),TEXT($B30,"mmm yyyy")) | J30: =IF(AND($E30="",$F30=""),"",SUM($E$8:$E30)) | L30: =IF($C30="","",COUNTIFS($C$8:$C30,$C30)) | M30: =IF($C30="","",$C30&"|"&$L30)
A31: =IF($C31="","",ROW()-7) | I31: =IF(OR($B31="",ISTEXT($B31)),IF($B31="Opening","Opening",""),TEXT($B31,"mmm yyyy")) | J31: =IF(AND($E31="",$F31=""),"",SUM($E$8:$E31)) | L31: =IF($C31="","",COUNTIFS($C$8:$C31,$C31)) | M31: =IF($C31="","",$C31&"|"&$L31)
A32: =IF($C32="","",ROW()-7) | I32: =IF(OR($B32="",ISTEXT($B32)),IF($B32="Opening","Opening",""),TEXT($B32,"mmm yyyy")) | J32: =IF(AND($E32="",$F32=""),"",SUM($E$8:$E32)) | L32: =IF($C32="","",COUNTIFS($C$8:$C32,$C32)) | M32: =IF($C32="","",$C32&"|"&$L32)
A33: =IF($C33="","",ROW()-7) | I33: =IF(OR($B33="",ISTEXT($B33)),IF($B33="Opening","Opening",""),TEXT($B33,"mmm yyyy")) | J33: =IF(AND($E33="",$F33=""),"",SUM($E$8:$E33)) | L33: =IF($C33="","",COUNTIFS($C$8:$C33,$C33)) | M33: =IF($C33="","",$C33&"|"&$L33)
A34: =IF($C34="","",ROW()-7) | I34: =IF(OR($B34="",ISTEXT($B34)),IF($B34="Opening","Opening",""),TEXT($B34,"mmm yyyy")) | J34: =IF(AND($E34="",$F34=""),"",SUM($E$8:$E34)) | L34: =IF($C34="","",COUNTIFS($C$8:$C34,$C34)) | M34: =IF($C34="","",$C34&"|"&$L34)
... A162: =IF($C162="","",ROW()-7) | I162: =IF(OR($B162="",ISTEXT($B162)),IF($B162="Opening","Opening",""),TEXT($B162,"mmm yyyy")) | J162: =IF(AND($E162="",$F162=""),"",SUM($E$8:$E162)) | L162: =IF($C162="","",COUNTIFS($C$8:$C162,$C162)) | M162: =IF($C162="","",$C162&"|"&$L162)

Sheet Charts
A1: INVESTMENT DASHBOARD — Ishwarya | Z1: Zero
A2: Charts and totals update automatically from the Investment Log. | Z2: One
Z3: Two
A4: TOTAL INVESTED (₹) | Z4: Three
A5: =SUM('Investment Log'!$E$8:$E$500) -> 1768750 | Z5: Four
A6: =IF($A$5=0,"","Rupees "&TRIM(IF(INT($A$5/10000000)>0,INDEX($Z$1:$Z$100,INT($A$5/10000000)+1)&" Crore ","")&IF(MOD(INT($A$5/100000),100)>0,INDEX($Z$1:$Z$100,MOD(INT($A$5/100000),100)+1)&" Lakh ","")&IF(MOD(INT($A$5/1000),100)>0,INDEX($Z$1:$Z$100,MOD(INT($A$5/1000),100)+1)&" Thousand ","")&IF(MOD(INT($A$5/100),10)>0,INDEX($Z$1:$Z$100,MOD(INT($A$5/100),10)+1)&" Hundred ","")&IF(MOD($A$5,100)>0,INDEX($Z$1:$Z$100,MOD($A$5,100)+1)&" ",""))&" Only") -> Rupees Seventeen Lakh Sixty Eight Thousand Seven Hundred Fifty Only | Z6: Five
Z7: Six
A8: Category | B8: Amount (₹) | C8: Share | D8: In Words | Z8: Seven
A9: Gold | B9: =SUMIF('Investment Log'!$C$8:$C$500,$A9,'Investment Log'!$E$8:$E$500) -> 420000 | C9: =IF($A$5=0,0,B9/$A$5) -> 0.23745583 | D9: =IF($B9=0,"","Rupees "&TRIM(IF(INT($B9/10000000)>0,INDEX($Z$1:$Z$100,INT($B9/10000000)+1)&" Crore ","")&IF(MOD(INT($B9/100000),100)>0,INDEX($Z$1:$Z$100,MOD(INT($B9/100000),100)+1)&" Lakh ","")&IF(MOD(INT($B9/1000),100)>0,INDEX($Z$1:$Z$100,MOD(INT($B9/1000),100)+1)&" Thousand ","")&IF(MOD(INT($B9/100),10)>0,INDEX($Z$1:$Z$100,MOD(INT($B9/100),10)+1)&" Hundred ","")&IF(MOD($B9,100)>0,INDEX($Z$1:$Z$100,MOD($B9,100)+1)&" ",""))&" Only") -> Rupees Four Lakh Twenty Thousand Only | Z9: Eight
A10: Fixed Deposit | B10: =SUMIF('Investment Log'!$C$8:$C$500,$A10,'Investment Log'!$E$8:$E$500) -> 250000 | C10: =IF($A$5=0,0,B10/$A$5) -> 0.14134276 | D10: =IF($B10=0,"","Rupees "&TRIM(IF(INT($B10/10000000)>0,INDEX($Z$1:$Z$100,INT($B10/10000000)+1)&" Crore ","")&IF(MOD(INT($B10/100000),100)>0,INDEX($Z$1:$Z$100,MOD(INT($B10/100000),100)+1)&" Lakh ","")&IF(MOD(INT($B10/1000),100)>0,INDEX($Z$1:$Z$100,MOD(INT($B10/1000),100)+1)&" Thousand ","")&IF(MOD(INT($B10/100),10)>0,INDEX($Z$1:$Z$100,MOD(INT($B10/100),10)+1)&" Hundred ","")&IF(MOD($B10,100)>0,INDEX($Z$1:$Z$100,MOD($B10,100)+1)&" ",""))&" Only") -> Rupees Two Lakh Fifty Thousand Only | Z10: Nine
A11: Mutual Funds | B11: =SUMIF('Investment Log'!$C$8:$C$500,$A11,'Investment Log'!$E$8:$E$500) -> 200000 | C11: =IF($A$5=0,0,B11/$A$5) -> 0.1130742 | D11: =IF($B11=0,"","Rupees "&TRIM(IF(INT($B11/10000000)>0,INDEX($Z$1:$Z$100,INT($B11/10000000)+1)&" Crore ","")&IF(MOD(INT($B11/100000),100)>0,INDEX($Z$1:$Z$100,MOD(INT($B11/100000),100)+1)&" Lakh ","")&IF(MOD(INT($B11/1000),100)>0,INDEX($Z$1:$Z$100,MOD(INT($B11/1000),100)+1)&" Thousand ","")&IF(MOD(INT($B11/100),10)>0,INDEX($Z$1:$Z$100,MOD(INT($B11/100),10)+1)&" Hundred ","")&IF(MOD($B11,100)>0,INDEX($Z$1:$Z$100,MOD($B11,100)+1)&" ",""))&" Only") -> Rupees Two Lakh Only | Z11: Ten
A12: Stocks | B12: =SUMIF('Investment Log'!$C$8:$C$500,$A12,'Investment Log'!$E$8:$E$500) -> 118750 | C12: =IF($A$5=0,0,B12/$A$5) -> 0.067137809 | D12: =IF($B12=0,"","Rupees "&TRIM(IF(INT($B12/10000000)>0,INDEX($Z$1:$Z$100,INT($B12/10000000)+1)&" Crore ","")&IF(MOD(INT($B12/100000),100)>0,INDEX($Z$1:$Z$100,MOD(INT($B12/100000),100)+1)&" Lakh ","")&IF(MOD(INT($B12/1000),100)>0,INDEX($Z$1:$Z$100,MOD(INT($B12/1000),100)+1)&" Thousand ","")&IF(MOD(INT($B12/100),10)>0,INDEX($Z$1:$Z$100,MOD(INT($B12/100),10)+1)&" Hundred ","")&IF(MOD($B12,100)>0,INDEX($Z$1:$Z$100,MOD($B12,100)+1)&" ",""))&" Only") -> Rupees One Lakh Eighteen Thousand Seven Hundred Fifty Only | Z12: Eleven
A13: IPO | B13: =SUMIF('Investment Log'!$C$8:$C$500,$A13,'Investment Log'!$E$8:$E$500) -> 30000 | C13: =IF($A$5=0,0,B13/$A$5) -> 0.016961131 | D13: =IF($B13=0,"","Rupees "&TRIM(IF(INT($B13/10000000)>0,INDEX($Z$1:$Z$100,INT($B13/10000000)+1)&" Crore ","")&IF(MOD(INT($B13/100000),100)>0,INDEX($Z$1:$Z$100,MOD(INT($B13/100000),100)+1)&" Lakh ","")&IF(MOD(INT($B13/1000),100)>0,INDEX($Z$1:$Z$100,MOD(INT($B13/1000),100)+1)&" Thousand ","")&IF(MOD(INT($B13/100),10)>0,INDEX($Z$1:$Z$100,MOD(INT($B13/100),10)+1)&" Hundred ","")&IF(MOD($B13,100)>0,INDEX($Z$1:$Z$100,MOD($B13,100)+1)&" ",""))&" Only") -> Rupees Thirty Thousand Only | Z13: Twelve
A14: Real Estate | B14: =SUMIF('Investment Log'!$C$8:$C$500,$A14,'Investment Log'!$E$8:$E$500) -> 750000 | C14: =IF($A$5=0,0,B14/$A$5) -> 0.42402827 | D14: =IF($B14=0,"","Rupees "&TRIM(IF(INT($B14/10000000)>0,INDEX($Z$1:$Z$100,INT($B14/10000000)+1)&" Crore ","")&IF(MOD(INT($B14/100000),100)>0,INDEX($Z$1:$Z$100,MOD(INT($B14/100000),100)+1)&" Lakh ","")&IF(MOD(INT($B14/1000),100)>0,INDEX($Z$1:$Z$100,MOD(INT($B14/1000),100)+1)&" Thousand ","")&IF(MOD(INT($B14/100),10)>0,INDEX($Z$1:$Z$100,MOD(INT($B14/100),10)+1)&" Hundred ","")&IF(MOD($B14,100)>0,INDEX($Z$1:$Z$100,MOD($B14,100)+1)&" ",""))&" Only") -> Rupees Seven Lakh Fifty Thousand Only | Z14: Thirteen
A15: TOTAL | B15: =SUM(B9:B14) -> 1768750 | C15: =SUM(C9:C14) -> 1 | Z15: Fourteen
Z16: Fifteen
Z17: Sixteen
A18: Month | B18: Invested (₹) | C18: Cumulative (₹) | Z18: Seventeen
A19: Dec 2025 | B19: =SUMIF('Investment Log'!$I$8:$I$500,$A19,'Investment Log'!$E$8:$E$500) -> 750000 | C19: =SUM($B$19:$B19) -> 750000 | Z19: Eighteen
A20: Jan 2026 | B20: =SUMIF('Investment Log'!$I$8:$I$500,$A20,'Investment Log'!$E$8:$E$500) -> 0 | C20: =SUM($B$19:$B20) -> 750000 | Z20: Nineteen
A21: Feb 2026 | B21: =SUMIF('Investment Log'!$I$8:$I$500,$A21,'Investment Log'!$E$8:$E$500) -> 350000 | C21: =SUM($B$19:$B21) -> 1100000 | Z21: Twenty
A22: Mar 2026 | B22: =SUMIF('Investment Log'!$I$8:$I$500,$A22,'Investment Log'!$E$8:$E$500) -> 100000 | C22: =SUM($B$19:$B22) -> 1200000 | Z22: Twenty One
A23: Apr 2026 | B23: =SUMIF('Investment Log'!$I$8:$I$500,$A23,'Investment Log'!$E$8:$E$500) -> 100000 | C23: =SUM($B$19:$B23) -> 1300000 | Z23: Twenty Two
A24: May 2026 | B24: =SUMIF('Investment Log'!$I$8:$I$500,$A24,'Investment Log'!$E$8:$E$500) -> 50000 | C24: =SUM($B$19:$B24) -> 1350000 | Z24: Twenty Three
A25: Jun 2026 | B25: =SUMIF('Investment Log'!$I$8:$I$500,$A25,'Investment Log'!$E$8:$E$500) -> 120000 | C25: =SUM($B$19:$B25) -> 1470000 | Z25: Twenty Four
A26: Jul 2026 | B26: =SUMIF('Investment Log'!$I$8:$I$500,$A26,'Investment Log'!$E$8:$E$500) -> 20000 | C26: =SUM($B$19:$B26) -> 1490000 | Z26: Twenty Five
A27: Aug 2026 | B27: =SUMIF('Investment Log'!$I$8:$I$500,$A27,'Investment Log'!$E$8:$E$500) -> 278750 | C27: =SUM($B$19:$B27) -> 1768750 | Z27: Twenty Six
A28: Sep 2026 | B28: =SUMIF('Investment Log'!$I$8:$I$500,$A28,'Investment Log'!$E$8:$E$500) -> 0 | C28: =SUM($B$19:$B28) -> 1768750 | Z28: Twenty Seven
A29: Oct 2026 | B29: =SUMIF('Investment Log'!$I$8:$I$500,$A29,'Investment Log'!$E$8:$E$500) -> 0 | C29: =SUM($B$19:$B29) -> 1768750 | Z29: Twenty Eight
A30: Nov 2026 | B30: =SUMIF('Investment Log'!$I$8:$I$500,$A30,'Investment Log'!$E$8:$E$500) -> 0 | C30: =SUM($B$19:$B30) -> 1768750 | Z30: Twenty Nine
A31: Dec 2026 | B31: =SUMIF('Investment Log'!$I$8:$I$500,$A31,'Investment Log'!$E$8:$E$500) -> 0 | C31: =SUM($B$19:$B31) -> 1768750 | Z31: Thirty
Z32: Thirty One
Z33: Thirty Two
Z34: Thirty Three
Z35: Thirty Four
Z36: Thirty Five
Z37: Thirty Six
Z38: Thirty Seven
Z39: Thirty Eight
Z40: Thirty Nine
...

Sheet Gold
A1: GOLD
A2: Auto-updates from the Investment Log — do not type here.
A4: TOTAL INVESTED (₹) | B4: TOTAL GOLD (g) | C4: RECORDS
A5: =SUMIF('Investment Log'!$C$8:$C$500,"Gold",'Investment Log'!$E$8:$E$500) -> 420000 | B5: =SUMIF('Investment Log'!$C$8:$C$500,"Gold",'Investment Log'!$F$8:$F$500) -> 137.5 | C5: =COUNTIF('Investment Log'!$C$8:$C$500,"Gold") -> 7
A7: Date | B7: Description / Name | C7: Amount Invested (₹) | D7: Gold (grams) | E7: Platform / Account | F7: Notes | G7: Running Gold (g) | H7: Running Total (₹)
A8: =IF($J8="","",INDEX('Investment Log'!$B:$B,$J8)) -> Opening | B8: =IF($J8="","",T(INDEX('Investment Log'!$D:$D,$J8))) -> Existing holding (opening) | C8: =IF($J8="","",INDEX('Investment Log'!$E:$E,$J8)) -> 0 | D8: =IF($J8="","",INDEX('Investment Log'!$F:$F,$J8)) -> 84.2 | E8: =IF($J8="","",T(INDEX('Investment Log'!$G:$G,$J8))) -> — | F8: =IF($J8="","",T(INDEX('Investment Log'!$H:$H,$J8))) -> Opening balance, pre-2025. Purchase cost not recorded. | G8: =IF($J8="","",SUM($D$8:$D8)) -> 84.2 | H8: =IF($J8="","",SUM($C$8:$C8)) -> 0 | J8: =IFERROR(MATCH("Gold|"&1,'Investment Log'!$M$8:$M$500,0)+7,"") -> 8
A9: =IF($J9="","",INDEX('Investment Log'!$B:$B,$J9)) -> 45658 | B9: =IF($J9="","",T(INDEX('Investment Log'!$D:$D,$J9))) | C9: =IF($J9="","",INDEX('Investment Log'!$E:$E,$J9)) -> 0 | D9: =IF($J9="","",INDEX('Investment Log'!$F:$F,$J9)) -> 12.9 | E9: =IF($J9="","",T(INDEX('Investment Log'!$G:$G,$J9))) -> — | F9: =IF($J9="","",T(INDEX('Investment Log'!$H:$H,$J9))) -> Bought 12.9 g. ₹ not recorded. Day not specified. | G9: =IF($J9="","",SUM($D$8:$D9)) -> 97.1 | H9: =IF($J9="","",SUM($C$8:$C9)) -> 0 | J9: =IFERROR(MATCH("Gold|"&2,'Investment Log'!$M$8:$M$500,0)+7,"") -> 9
A10: =IF($J10="","",INDEX('Investment Log'!$B:$B,$J10)) -> 45717 | B10: =IF($J10="","",T(INDEX('Investment Log'!$D:$D,$J10))) | C10: =IF($J10="","",INDEX('Investment Log'!$E:$E,$J10)) -> 0 | D10: =IF($J10="","",INDEX('Investment Log'!$F:$F,$J10)) -> 10.9 | E10: =IF($J10="","",T(INDEX('Investment Log'!$G:$G,$J10))) -> — | F10: =IF($J10="","",T(INDEX('Investment Log'!$H:$H,$J10))) -> Bought 10.9 g. ₹ not recorded. Day not specified. | G10: =IF($J10="","",SUM($D$8:$D10)) -> 108 | H10: =IF($J10="","",SUM($C$8:$C10)) -> 0 | J10: =IFERROR(MATCH("Gold|"&3,'Investment Log'!$M$8:$M$500,0)+7,"") -> 10
A11: =IF($J11="","",INDEX('Investment Log'!$B:$B,$J11)) -> 46082 | B11: =IF($J11="","",T(INDEX('Investment Log'!$D:$D,$J11))) | C11: =IF($J11="","",INDEX('Investment Log'!$E:$E,$J11)) -> 100000 | D11: =IF($J11="","",INDEX('Investment Log'!$F:$F,$J11)) -> 6.62 | E11: =IF($J11="","",T(INDEX('Investment Log'!$G:$G,$J11))) -> — | F11: =IF($J11="","",T(INDEX('Investment Log'!$H:$H,$J11))) -> ₹1L → 6.62 g. Day not specified. | G11: =IF($J11="","",SUM($D$8:$D11)) -> 114.62 | H11: =IF($J11="","",SUM($C$8:$C11)) -> 100000 | J11: =IFERROR(MATCH("Gold|"&4,'Investment Log'!$M$8:$M$500,0)+7,"") -> 14
A12: =IF($J12="","",INDEX('Investment Log'!$B:$B,$J12)) -> 46113 | B12: =IF($J12="","",T(INDEX('Investment Log'!$D:$D,$J12))) | C12: =IF($J12="","",INDEX('Investment Log'!$E:$E,$J12)) -> 100000 | D12: =IF($J12="","",INDEX('Investment Log'!$F:$F,$J12)) -> 6.58 | E12: =IF($J12="","",T(INDEX('Investment Log'!$G:$G,$J12))) -> — | F12: =IF($J12="","",T(INDEX('Investment Log'!$H:$H,$J12))) -> ₹1L → 6.58 g. Day not specified. | G12: =IF($J12="","",SUM($D$8:$D12)) -> 121.2 | H12: =IF($J12="","",SUM($C$8:$C12)) -> 200000 | J12: =IFERROR(MATCH("Gold|"&5,'Investment Log'!$M$8:$M$500,0)+7,"") -> 15
A13: =IF($J13="","",INDEX('Investment Log'!$B:$B,$J13)) -> 46174 | B13: =IF($J13="","",T(INDEX('Investment Log'!$D:$D,$J13))) | C13: =IF($J13="","",INDEX('Investment Log'!$E:$E,$J13)) -> 120000 | D13: =IF($J13="","",INDEX('Investment Log'!$F:$F,$J13)) -> 10 | E13: =IF($J13="","",T(INDEX('Investment Log'!$G:$G,$J13))) -> — | F13: =IF($J13="","",T(INDEX('Investment Log'!$H:$H,$J13))) -> ₹1.2L → 10 g. Day not specified. | G13: =IF($J13="","",SUM($D$8:$D13)) -> 131.2 | H13: =IF($J13="","",SUM($C$8:$C13)) -> 320000 | J13: =IFERROR(MATCH("Gold|"&6,'Investment Log'!$M$8:$M$500,0)+7,"") -> 17
A14: =IF($J14="","",INDEX('Investment Log'!$B:$B,$J14)) -> 46237 | B14: =IF($J14="","",T(INDEX('Investment Log'!$D:$D,$J14))) | C14: =IF($J14="","",INDEX('Investment Log'!$E:$E,$J14)) -> 100000 | D14: =IF($J14="","",INDEX('Investment Log'!$F:$F,$J14)) -> 6.3 | E14: =IF($J14="","",T(INDEX('Investment Log'!$G:$G,$J14))) -> — | F14: =IF($J14="","",T(INDEX('Investment Log'!$H:$H,$J14))) -> ₹1L → 6.3 g. Date assumed = 3 Aug. | G14: =IF($J14="","",SUM($D$8:$D14)) -> 137.5 | H14: =IF($J14="","",SUM($C$8:$C14)) -> 420000 | J14: =IFERROR(MATCH("Gold|"&7,'Investment Log'!$M$8:$M$500,0)+7,"") -> 21
A15: =IF($J15="","",INDEX('Investment Log'!$B:$B,$J15)) | B15: =IF($J15="","",T(INDEX('Investment Log'!$D:$D,$J15))) | C15: =IF($J15="","",INDEX('Investment Log'!$E:$E,$J15)) | D15: =IF($J15="","",INDEX('Investment Log'!$F:$F,$J15)) | E15: =IF($J15="","",T(INDEX('Investment Log'!$G:$G,$J15))) | F15: =IF($J15="","",T(INDEX('Investment Log'!$H:$H,$J15))) | G15: =IF($J15="","",SUM($D$8:$D15)) | H15: =IF($J15="","",SUM($C$8:$C15)) | J15: =IFERROR(MATCH("Gold|"&8,'Investment Log'!$M$8:$M$500,0)+7,"")
A16: =IF($J16="","",INDEX('Investment Log'!$B:$B,$J16)) | B16: =IF($J16="","",T(INDEX('Investment Log'!$D:$D,$J16))) | C16: =IF($J16="","",INDEX('Investment Log'!$E:$E,$J16)) | D16: =IF($J16="","",INDEX('Investment Log'!$F:$F,$J16)) | E16: =IF($J16="","",T(INDEX('Investment Log'!$G:$G,$J16))) | F16: =IF($J16="","",T(INDEX('Investment Log'!$H:$H,$J16))) | G16: =IF($J16="","",SUM($D$8:$D16)) | H16: =IF($J16="","",SUM($C$8:$C16)) | J16: =IFERROR(MATCH("Gold|"&9,'Investment Log'!$M$8:$M$500,0)+7,"")
A17: =IF($J17="","",INDEX('Investment Log'!$B:$B,$J17)) | B17: =IF($J17="","",T(INDEX('Investment Log'!$D:$D,$J17))) | C17: =IF($J17="","",INDEX('Investment Log'!$E:$E,$J17)) | D17: =IF($J17="","",INDEX('Investment Log'!$F:$F,$J17)) | E17: =IF($J17="","",T(INDEX('Investment Log'!$G:$G,$J17))) | F17: =IF($J17="","",T(INDEX('Investment Log'!$H:$H,$J17))) | G17: =IF($J17="","",SUM($D$8:$D17)) | H17: =IF($J17="","",SUM($C$8:$C17)) | J17: =IFERROR(MATCH("Gold|"&10,'Investment Log'!$M$8:$M$500,0)+7,"")
A18: =IF($J18="","",INDEX('Investment Log'!$B:$B,$J18)) | B18: =IF($J18="","",T(INDEX('Investment Log'!$D:$D,$J18))) | C18: =IF($J18="","",INDEX('Investment Log'!$E:$E,$J18)) | D18: =IF($J18="","",INDEX('Investment Log'!$F:$F,$J18)) | E18: =IF($J18="","",T(INDEX('Investment Log'!$G:$G,$J18))) | F18: =IF($J18="","",T(INDEX('Investment Log'!$H:$H,$J18))) | G18: =IF($J18="","",SUM($D$8:$D18)) | H18: =IF($J18="","",SUM($C$8:$C18)) | J18: =IFERROR(MATCH("Gold|"&11,'Investment Log'!$M$8:$M$500,0)+7,"")
A19: =IF($J19="","",INDEX('Investment Log'!$B:$B,$J19)) | B19: =IF($J19="","",T(INDEX('Investment Log'!$D:$D,$J19))) | C19: =IF($J19="","",INDEX('Investment Log'!$E:$E,$J19)) | D19: =IF($J19="","",INDEX('Investment Log'!$F:$F,$J19)) | E19: =IF($J19="","",T(INDEX('Investment Log'!$G:$G,$J19))) | F19: =IF($J19="","",T(INDEX('Investment Log'!$H:$H,$J19))) | G19: =IF($J19="","",SUM($D$8:$D19)) | H19: =IF($J19="","",SUM($C$8:$C19)) | J19: =IFERROR(MATCH("Gold|"&12,'Investment Log'!$M$8:$M$500,0)+7,"")
A20: =IF($J20="","",INDEX('Investment Log'!$B:$B,$J20)) | B20: =IF($J20="","",T(INDEX('Investment Log'!$D:$D,$J20))) | C20: =IF($J20="","",INDEX('Investment Log'!$E:$E,$J20)) | D20: =IF($J20="","",INDEX('Investment Log'!$F:$F,$J20)) | E20: =IF($J20="","",T(INDEX('Investment Log'!$G:$G,$J20))) | F20: =IF($J20="","",T(INDEX('Investment Log'!$H:$H,$J20))) | G20: =IF($J20="","",SUM($D$8:$D20)) | H20: =IF($J20="","",SUM($C$8:$C20)) | J20: =IFERROR(MATCH("Gold|"&13,'Investment Log'!$M$8:$M$500,0)+7,"")
A21: =IF($J21="","",INDEX('Investment Log'!$B:$B,$J21)) | B21: =IF($J21="","",T(INDEX('Investment Log'!$D:$D,$J21))) | C21: =IF($J21="","",INDEX('Investment Log'!$E:$E,$J21)) | D21: =IF($J21="","",INDEX('Investment Log'!$F:$F,$J21)) | E21: =IF($J21="","",T(INDEX('Investment Log'!$G:$G,$J21))) | F21: =IF($J21="","",T(INDEX('Investment Log'!$H:$H,$J21))) | G21: =IF($J21="","",SUM($D$8:$D21)) | H21: =IF($J21="","",SUM($C$8:$C21)) | J21: =IFERROR(MATCH("Gold|"&14,'Investment Log'!$M$8:$M$500,0)+7,"")
A22: =IF($J22="","",INDEX('Investment Log'!$B:$B,$J22)) | B22: =IF($J22="","",T(INDEX('Investment Log'!$D:$D,$J22))) | C22: =IF($J22="","",INDEX('Investment Log'!$E:$E,$J22)) | D22: =IF($J22="","",INDEX('Investment Log'!$F:$F,$J22)) | E22: =IF($J22="","",T(INDEX('Investment Log'!$G:$G,$J22))) | F22: =IF($J22="","",T(INDEX('Investment Log'!$H:$H,$J22))) | G22: =IF($J22="","",SUM($D$8:$D22)) | H22: =IF($J22="","",SUM($C$8:$C22)) | J22: =IFERROR(MATCH("Gold|"&15,'Investment Log'!$M$8:$M$500,0)+7,"")
A23: =IF($J23="","",INDEX('Investment Log'!$B:$B,$J23)) | B23: =IF($J23="","",T(INDEX('Investment Log'!$D:$D,$J23))) | C23: =IF($J23="","",INDEX('Investment Log'!$E:$E,$J23)) | D23: =IF($J23="","",INDEX('Investment Log'!$F:$F,$J23)) | E23: =IF($J23="","",T(INDEX('Investment Log'!$G:$G,$J23))) | F23: =IF($J23="","",T(INDEX('Investment Log'!$H:$H,$J23))) | G23: =IF($J23="","",SUM($D$8:$D23)) | H23: =IF($J23="","",SUM($C$8:$C23)) | J23: =IFERROR(MATCH("Gold|"&16,'Investment Log'!$M$8:$M$500,0)+7,"")
A24: =IF($J24="","",INDEX('Investment Log'!$B:$B,$J24)) | B24: =IF($J24="","",T(INDEX('Investment Log'!$D:$D,$J24))) | C24: =IF($J24="","",INDEX('Investment Log'!$E:$E,$J24)) | D24: =IF($J24="","",INDEX('Investment Log'!$F:$F,$J24)) | E24: =IF($J24="","",T(INDEX('Investment Log'!$G:$G,$J24))) | F24: =IF($J24="","",T(INDEX('Investment Log'!$H:$H,$J24))) | G24: =IF($J24="","",SUM($D$8:$D24)) | H24: =IF($J24="","",SUM($C$8:$C24)) | J24: =IFERROR(MATCH("Gold|"&17,'Investment Log'!$M$8:$M$500,0)+7,"")
A25: =IF($J25="","",INDEX('Investment Log'!$B:$B,$J25)) | B25: =IF($J25="","",T(INDEX('Investment Log'!$D:$D,$J25))) | C25: =IF($J25="","",INDEX('Investment Log'!$E:$E,$J25)) | D25: =IF($J25="","",INDEX('Investment Log'!$F:$F,$J25)) | E25: =IF($J25="","",T(INDEX('Investment Log'!$G:$G,$J25))) | F25: =IF($J25="","",T(INDEX('Investment Log'!$H:$H,$J25))) | G25: =IF($J25="","",SUM($D$8:$D25)) | H25: =IF($J25="","",SUM($C$8:$C25)) | J25: =IFERROR(MATCH("Gold|"&18,'Investment Log'!$M$8:$M$500,0)+7,"")
A26: =IF($J26="","",INDEX('Investment Log'!$B:$B,$J26)) | B26: =IF($J26="","",T(INDEX('Investment Log'!$D:$D,$J26))) | C26: =IF($J26="","",INDEX('Investment Log'!$E:$E,$J26)) | D26: =IF($J26="","",INDEX('Investment Log'!$F:$F,$J26)) | E26: =IF($J26="","",T(INDEX('Investment Log'!$G:$G,$J26))) | F26: =IF($J26="","",T(INDEX('Investment Log'!$H:$H,$J26))) | G26: =IF($J26="","",SUM($D$8:$D26)) | H26: =IF($J26="","",SUM($C$8:$C26)) | J26: =IFERROR(MATCH("Gold|"&19,'Investment Log'!$M$8:$M$500,0)+7,"")
A27: =IF($J27="","",INDEX('Investment Log'!$B:$B,$J27)) | B27: =IF($J27="","",T(INDEX('Investment Log'!$D:$D,$J27))) | C27: =IF($J27="","",INDEX('Investment Log'!$E:$E,$J27)) | D27: =IF($J27="","",INDEX('Investment Log'!$F:$F,$J27)) | E27: =IF($J27="","",T(INDEX('Investment Log'!$G:$G,$J27))) | F27: =IF($J27="","",T(INDEX('Investment Log'!$H:$H,$J27))) | G27: =IF($J27="","",SUM($D$8:$D27)) | H27: =IF($J27="","",SUM($C$8:$C27)) | J27: =IFERROR(MATCH("Gold|"&20,'Investment Log'!$M$8:$M$500,0)+7,"")
A28: =IF($J28="","",INDEX('Investment Log'!$B:$B,$J28)) | B28: =IF($J28="","",T(INDEX('Investment Log'!$D:$D,$J28))) | C28: =IF($J28="","",INDEX('Investment Log'!$E:$E,$J28)) | D28: =IF($J28="","",INDEX('Investment Log'!$F:$F,$J28)) | E28: =IF($J28="","",T(INDEX('Investment Log'!$G:$G,$J28))) | F28: =IF($J28="","",T(INDEX('Investment Log'!$H:$H,$J28))) | G28: =IF($J28="","",SUM($D$8:$D28)) | H28: =IF($J28="","",SUM($C$8:$C28)) | J28: =IFERROR(MATCH("Gold|"&21,'Investment Log'!$M$8:$M$500,0)+7,"")
A29: =IF($J29="","",INDEX('Investment Log'!$B:$B,$J29)) | B29: =IF($J29="","",T(INDEX('Investment Log'!$D:$D,$J29))) | C29: =IF($J29="","",INDEX('Investment Log'!$E:$E,$J29)) | D29: =IF($J29="","",INDEX('Investment Log'!$F:$F,$J29)) | E29: =IF($J29="","",T(INDEX('Investment Log'!$G:$G,$J29))) | F29: =IF($J29="","",T(INDEX('Investment Log'!$H:$H,$J29))) | G29: =IF($J29="","",SUM($D$8:$D29)) | H29: =IF($J29="","",SUM($C$8:$C29)) | J29: =IFERROR(MATCH("Gold|"&22,'Investment Log'!$M$8:$M$500,0)+7,"")
A30: =IF($J30="","",INDEX('Investment Log'!$B:$B,$J30)) | B30: =IF($J30="","",T(INDEX('Investment Log'!$D:$D,$J30))) | C30: =IF($J30="","",INDEX('Investment Log'!$E:$E,$J30)) | D30: =IF($J30="","",INDEX('Investment Log'!$F:$F,$J30)) | E30: =IF($J30="","",T(INDEX('Investment Log'!$G:$G,$J30))) | F30: =IF($J30="","",T(INDEX('Investment Log'!$H:$H,$J30))) | G30: =IF($J30="","",SUM($D$8:$D30)) | H30: =IF($J30="","",SUM($C$8:$C30)) | J30: =IFERROR(MATCH("Gold|"&23,'Investment Log'!$M$8:$M$500,0)+7,"")
A31: =IF($J31="","",INDEX('Investment Log'!$B:$B,$J31)) | B31: =IF($J31="","",T(INDEX('Investment Log'!$D:$D,$J31))) | C31: =IF($J31="","",INDEX('Investment Log'!$E:$E,$J31)) | D31: =IF($J31="","",INDEX('Investment Log'!$F:$F,$J31)) | E31: =IF($J31="","",T(INDEX('Investment Log'!$G:$G,$J31))) | F31: =IF($J31="","",T(INDEX('Investment Log'!$H:$H,$J31))) | G31: =IF($J31="","",SUM($D$8:$D31)) | H31: =IF($J31="","",SUM($C$8:$C31)) | J31: =IFERROR(MATCH("Gold|"&24,'Investment Log'!$M$8:$M$500,0)+7,"")
A32: =IF($J32="","",INDEX('Investment Log'!$B:$B,$J32)) | B32: =IF($J32="","",T(INDEX('Investment Log'!$D:$D,$J32))) | C32: =IF($J32="","",INDEX('Investment Log'!$E:$E,$J32)) | D32: =IF($J32="","",INDEX('Investment Log'!$F:$F,$J32)) | E32: =IF($J32="","",T(INDEX('Investment Log'!$G:$G,$J32))) | F32: =IF($J32="","",T(INDEX('Investment Log'!$H:$H,$J32))) | G32: =IF($J32="","",SUM($D$8:$D32)) | H32: =IF($J32="","",SUM($C$8:$C32)) | J32: =IFERROR(MATCH("Gold|"&25,'Investment Log'!$M$8:$M$500,0)+7,"")
A33: =IF($J33="","",INDEX('Investment Log'!$B:$B,$J33)) | B33: =IF($J33="","",T(INDEX('Investment Log'!$D:$D,$J33))) | C33: =IF($J33="","",INDEX('Investment Log'!$E:$E,$J33)) | D33: =IF($J33="","",INDEX('Investment Log'!$F:$F,$J33)) | E33: =IF($J33="","",T(INDEX('Investment Log'!$G:$G,$J33))) | F33: =IF($J33="","",T(INDEX('Investment Log'!$H:$H,$J33))) | G33: =IF($J33="","",SUM($D$8:$D33)) | H33: =IF($J33="","",SUM($C$8:$C33)) | J33: =IFERROR(MATCH("Gold|"&26,'Investment Log'!$M$8:$M$500,0)+7,"")
A34: =IF($J34="","",INDEX('Investment Log'!$B:$B,$J34)) | B34: =IF($J34="","",T(INDEX('Investment Log'!$D:$D,$J34))) | C34: =IF($J34="","",INDEX('Investment Log'!$E:$E,$J34)) | D34: =IF($J34="","",INDEX('Investment Log'!$F:$F,$J34)) | E34: =IF($J34="","",T(INDEX('Investment Log'!$G:$G,$J34))) | F34: =IF($J34="","",T(INDEX('Investment Log'!$H:$H,$J34))) | G34: =IF($J34="","",SUM($D$8:$D34)) | H34: =IF($J34="","",SUM($C$8:$C34)) | J34: =IFERROR(MATCH("Gold|"&27,'Investment Log'!$M$8:$M$500,0)+7,"")
A35: =IF($J35="","",INDEX('Investment Log'!$B:$B,$J35)) | B35: =IF($J35="","",T(INDEX('Investment Log'!$D:$D,$J35))) | C35: =IF($J35="","",INDEX('Investment Log'!$E:$E,$J35)) | D35: =IF($J35="","",INDEX('Investment Log'!$F:$F,$J35)) | E35: =IF($J35="","",T(INDEX('Investment Log'!$G:$G,$J35))) | F35: =IF($J35="","",T(INDEX('Investment Log'!$H:$H,$J35))) | G35: =IF($J35="","",SUM($D$8:$D35)) | H35: =IF($J35="","",SUM($C$8:$C35)) | J35: =IFERROR(MATCH("Gold|"&28,'Investment Log'!$M$8:$M$500,0)+7,"")
A36: =IF($J36="","",INDEX('Investment Log'!$B:$B,$J36)) | B36: =IF($J36="","",T(INDEX('Investment Log'!$D:$D,$J36))) | C36: =IF($J36="","",INDEX('Investment Log'!$E:$E,$J36)) | D36: =IF($J36="","",INDEX('Investment Log'!$F:$F,$J36)) | E36: =IF($J36="","",T(INDEX('Investment Log'!$G:$G,$J36))) | F36: =IF($J36="","",T(INDEX('Investment Log'!$H:$H,$J36))) | G36: =IF($J36="","",SUM($D$8:$D36)) | H36: =IF($J36="","",SUM($C$8:$C36)) | J36: =IFERROR(MATCH("Gold|"&29,'Investment Log'!$M$8:$M$500,0)+7,"")
A37: =IF($J37="","",INDEX('Investment Log'!$B:$B,$J37)) | B37: =IF($J37="","",T(INDEX('Investment Log'!$D:$D,$J37))) | C37: =IF($J37="","",INDEX('Investment Log'!$E:$E,$J37)) | D37: =IF($J37="","",INDEX('Investment Log'!$F:$F,$J37)) | E37: =IF($J37="","",T(INDEX('Investment Log'!$G:$G,$J37))) | F37: =IF($J37="","",T(INDEX('Investment Log'!$H:$H,$J37))) | G37: =IF($J37="","",SUM($D$8:$D37)) | H37: =IF($J37="","",SUM($C$8:$C37)) | J37: =IFERROR(MATCH("Gold|"&30,'Investment Log'!$M$8:$M$500,0)+7,"")
A38: =IF($J38="","",INDEX('Investment Log'!$B:$B,$J38)) | B38: =IF($J38="","",T(INDEX('Investment Log'!$D:$D,$J38))) | C38: =IF($J38="","",INDEX('Investment Log'!$E:$E,$J38)) | D38: =IF($J38="","",INDEX('Investment Log'!$F:$F,$J38)) | E38: =IF($J38="","",T(INDEX('Investment Log'!$G:$G,$J38))) | F38: =IF($J38="","",T(INDEX('Investment Log'!$H:$H,$J38))) | G38: =IF($J38="","",SUM($D$8:$D38)) | H38: =IF($J38="","",SUM($C$8:$C38)) | J38: =IFERROR(MATCH("Gold|"&31,'Investment Log'!$M$8:$M$500,0)+7,"")
A39: =IF($J39="","",INDEX('Investment Log'!$B:$B,$J39)) | B39: =IF($J39="","",T(INDEX('Investment Log'!$D:$D,$J39))) | C39: =IF($J39="","",INDEX('Investment Log'!$E:$E,$J39)) | D39: =IF($J39="","",INDEX('Investment Log'!$F:$F,$J39)) | E39: =IF($J39="","",T(INDEX('Investment Log'!$G:$G,$J39))) | F39: =IF($J39="","",T(INDEX('Investment Log'!$H:$H,$J39))) | G39: =IF($J39="","",SUM($D$8:$D39)) | H39: =IF($J39="","",SUM($C$8:$C39)) | J39: =IFERROR(MATCH("Gold|"&32,'Investment Log'!$M$8:$M$500,0)+7,"")
A40: =IF($J40="","",INDEX('Investment Log'!$B:$B,$J40)) | B40: =IF($J40="","",T(INDEX('Investment Log'!$D:$D,$J40))) | C40: =IF($J40="","",INDEX('Investment Log'!$E:$E,$J40)) | D40: =IF($J40="","",INDEX('Investment Log'!$F:$F,$J40)) | E40: =IF($J40="","",T(INDEX('Investment Log'!$G:$G,$J40))) | F40: =IF($J40="","",T(INDEX('Investment Log'!$H:$H,$J40))) | G40: =IF($J40="","",SUM($D$8:$D40)) | H40: =IF($J40="","",SUM($C$8:$C40)) | J40: =IFERROR(MATCH("Gold|"&33,'Investment Log'!$M$8:$M$500,0)+7,"")
A41: =IF($J41="","",INDEX('Investment Log'!$B:$B,$J41)) | B41: =IF($J41="","",T(INDEX('Investment Log'!$D:$D,$J41))) | C41: =IF($J41="","",INDEX('Investment Log'!$E:$E,$J41)) | D41: =IF($J41="","",INDEX('Investment Log'!$F:$F,$J41)) | E41: =IF($J41="","",T(INDEX('Investment Log'!$G:$G,$J41))) | F41: =IF($J41="","",T(INDEX('Investment Log'!$H:$H,$J41))) | G41: =IF($J41="","",SUM($D$8:$D41)) | H41: =IF($J41="","",SUM($C$8:$C41)) | J41: =IFERROR(MATCH("Gold|"&34,'Investment Log'!$M$8:$M$500,0)+7,"")
A42: =IF($J42="","",INDEX('Investment Log'!$B:$B,$J42)) | B42: =IF($J42="","",T(INDEX('Investment Log'!$D:$D,$J42))) | C42: =IF($J42="","",INDEX('Investment Log'!$E:$E,$J42)) | D42: =IF($J42="","",INDEX('Investment Log'!$F:$F,$J42)) | E42: =IF($J42="","",T(INDEX('Investment Log'!$G:$G,$J42))) | F42: =IF($J42="","",T(INDEX('Investment Log'!$H:$H,$J42))) | G42: =IF($J42="","",SUM($D$8:$D42)) | H42: =IF($J42="","",SUM($C$8:$C42)) | J42: =IFERROR(MATCH("Gold|"&35,'Investment Log'!$M$8:$M$500,0)+7,"")
...

Sheet Fixed Deposit
A1: FIXED DEPOSIT
A2: Auto-updates from the Investment Log — do not type here.
A4: TOTAL INVESTED (₹) | B4: RECORDS
A5: =SUMIF('Investment Log'!$C$8:$C$500,"Fixed Deposit",'Investment Log'!$E$8:$E$500) -> 250000 | B5: =COUNTIF('Investment Log'!$C$8:$C$500,"Fixed Deposit") -> 3
A7: Date | B7: Description / Name | C7: Amount Invested (₹) | D7: Platform / Account | E7: Notes | F7: Running Total (₹)
A8: =IF($H8="","",INDEX('Investment Log'!$B:$B,$H8)) -> 46054 | B8: =IF($H8="","",T(INDEX('Investment Log'!$D:$D,$H8))) -> ICICI FD | C8: =IF($H8="","",INDEX('Investment Log'!$E:$E,$H8)) -> 150000 | D8: =IF($H8="","",T(INDEX('Investment Log'!$G:$G,$H8))) -> ICICI | E8: =IF($H8="","",T(INDEX('Investment Log'!$H:$H,$H8))) -> Day not specified. Rate / tenure not recorded. | F8: =IF($H8="","",SUM($C$8:$C8)) -> 150000 | H8: =IFERROR(MATCH("Fixed Deposit|"&1,'Investment Log'!$M$8:$M$500,0)+7,"") -> 13
A9: =IF($H9="","",INDEX('Investment Log'!$B:$B,$H9)) -> 46143 | B9: =IF($H9="","",T(INDEX('Investment Log'!$D:$D,$H9))) -> FD | C9: =IF($H9="","",INDEX('Investment Log'!$E:$E,$H9)) -> 50000 | D9: =IF($H9="","",T(INDEX('Investment Log'!$G:$G,$H9))) -> — | E9: =IF($H9="","",T(INDEX('Investment Log'!$H:$H,$H9))) -> Day / bank not specified. | F9: =IF($H9="","",SUM($C$8:$C9)) -> 200000 | H9: =IFERROR(MATCH("Fixed Deposit|"&2,'Investment Log'!$M$8:$M$500,0)+7,"") -> 16
A10: =IF($H10="","",INDEX('Investment Log'!$B:$B,$H10)) -> 46265 | B10: =IF($H10="","",T(INDEX('Investment Log'!$D:$D,$H10))) -> ICICI FD | C10: =IF($H10="","",INDEX('Investment Log'!$E:$E,$H10)) -> 50000 | D10: =IF($H10="","",T(INDEX('Investment Log'!$G:$G,$H10))) -> ICICI | E10: =IF($H10="","",T(INDEX('Investment Log'!$H:$H,$H10))) -> 3.5 years @ 6.5% interest. | F10: =IF($H10="","",SUM($C$8:$C10)) -> 250000 | H10: =IFERROR(MATCH("Fixed Deposit|"&3,'Investment Log'!$M$8:$M$500,0)+7,"") -> 22
A11: =IF($H11="","",INDEX('Investment Log'!$B:$B,$H11)) | B11: =IF($H11="","",T(INDEX('Investment Log'!$D:$D,$H11))) | C11: =IF($H11="","",INDEX('Investment Log'!$E:$E,$H11)) | D11: =IF($H11="","",T(INDEX('Investment Log'!$G:$G,$H11))) | E11: =IF($H11="","",T(INDEX('Investment Log'!$H:$H,$H11))) | F11: =IF($H11="","",SUM($C$8:$C11)) | H11: =IFERROR(MATCH("Fixed Deposit|"&4,'Investment Log'!$M$8:$M$500,0)+7,"")
A12: =IF($H12="","",INDEX('Investment Log'!$B:$B,$H12)) | B12: =IF($H12="","",T(INDEX('Investment Log'!$D:$D,$H12))) | C12: =IF($H12="","",INDEX('Investment Log'!$E:$E,$H12)) | D12: =IF($H12="","",T(INDEX('Investment Log'!$G:$G,$H12))) | E12: =IF($H12="","",T(INDEX('Investment Log'!$H:$H,$H12))) | F12: =IF($H12="","",SUM($C$8:$C12)) | H12: =IFERROR(MATCH("Fixed Deposit|"&5,'Investment Log'!$M$8:$M$500,0)+7,"")
A13: =IF($H13="","",INDEX('Investment Log'!$B:$B,$H13)) | B13: =IF($H13="","",T(INDEX('Investment Log'!$D:$D,$H13))) | C13: =IF($H13="","",INDEX('Investment Log'!$E:$E,$H13)) | D13: =IF($H13="","",T(INDEX('Investment Log'!$G:$G,$H13))) | E13: =IF($H13="","",T(INDEX('Investment Log'!$H:$H,$H13))) | F13: =IF($H13="","",SUM($C$8:$C13)) | H13: =IFERROR(MATCH("Fixed Deposit|"&6,'Investment Log'!$M$8:$M$500,0)+7,"")
A14: =IF($H14="","",INDEX('Investment Log'!$B:$B,$H14)) | B14: =IF($H14="","",T(INDEX('Investment Log'!$D:$D,$H14))) | C14: =IF($H14="","",INDEX('Investment Log'!$E:$E,$H14)) | D14: =IF($H14="","",T(INDEX('Investment Log'!$G:$G,$H14))) | E14: =IF($H14="","",T(INDEX('Investment Log'!$H:$H,$H14))) | F14: =IF($H14="","",SUM($C$8:$C14)) | H14: =IFERROR(MATCH("Fixed Deposit|"&7,'Investment Log'!$M$8:$M$500,0)+7,"")
A15: =IF($H15="","",INDEX('Investment Log'!$B:$B,$H15)) | B15: =IF($H15="","",T(INDEX('Investment Log'!$D:$D,$H15))) | C15: =IF($H15="","",INDEX('Investment Log'!$E:$E,$H15)) | D15: =IF($H15="","",T(INDEX('Investment Log'!$G:$G,$H15))) | E15: =IF($H15="","",T(INDEX('Investment Log'!$H:$H,$H15))) | F15: =IF($H15="","",SUM($C$8:$C15)) | H15: =IFERROR(MATCH("Fixed Deposit|"&8,'Investment Log'!$M$8:$M$500,0)+7,"")
A16: =IF($H16="","",INDEX('Investment Log'!$B:$B,$H16)) | B16: =IF($H16="","",T(INDEX('Investment Log'!$D:$D,$H16))) | C16: =IF($H16="","",INDEX('Investment Log'!$E:$E,$H16)) | D16: =IF($H16="","",T(INDEX('Investment Log'!$G:$G,$H16))) | E16: =IF($H16="","",T(INDEX('Investment Log'!$H:$H,$H16))) | F16: =IF($H16="","",SUM($C$8:$C16)) | H16: =IFERROR(MATCH("Fixed Deposit|"&9,'Investment Log'!$M$8:$M$500,0)+7,"")
A17: =IF($H17="","",INDEX('Investment Log'!$B:$B,$H17)) | B17: =IF($H17="","",T(INDEX('Investment Log'!$D:$D,$H17))) | C17: =IF($H17="","",INDEX('Investment Log'!$E:$E,$H17)) | D17: =IF($H17="","",T(INDEX('Investment Log'!$G:$G,$H17))) | E17: =IF($H17="","",T(INDEX('Investment Log'!$H:$H,$H17))) | F17: =IF($H17="","",SUM($C$8:$C17)) | H17: =IFERROR(MATCH("Fixed Deposit|"&10,'Investment Log'!$M$8:$M$500,0)+7,"")
A18: =IF($H18="","",INDEX('Investment Log'!$B:$B,$H18)) | B18: =IF($H18="","",T(INDEX('Investment Log'!$D:$D,$H18))) | C18: =IF($H18="","",INDEX('Investment Log'!$E:$E,$H18)) | D18: =IF($H18="","",T(INDEX('Investment Log'!$G:$G,$H18))) | E18: =IF($H18="","",T(INDEX('Investment Log'!$H:$H,$H18))) | F18: =IF($H18="","",SUM($C$8:$C18)) | H18: =IFERROR(MATCH("Fixed Deposit|"&11,'Investment Log'!$M$8:$M$500,0)+7,"")
A19: =IF($H19="","",INDEX('Investment Log'!$B:$B,$H19)) | B19: =IF($H19="","",T(INDEX('Investment Log'!$D:$D,$H19))) | C19: =IF($H19="","",INDEX('Investment Log'!$E:$E,$H19)) | D19: =IF($H19="","",T(INDEX('Investment Log'!$G:$G,$H19))) | E19: =IF($H19="","",T(INDEX('Investment Log'!$H:$H,$H19))) | F19: =IF($H19="","",SUM($C$8:$C19)) | H19: =IFERROR(MATCH("Fixed Deposit|"&12,'Investment Log'!$M$8:$M$500,0)+7,"")
A20: =IF($H20="","",INDEX('Investment Log'!$B:$B,$H20)) | B20: =IF($H20="","",T(INDEX('Investment Log'!$D:$D,$H20))) | C20: =IF($H20="","",INDEX('Investment Log'!$E:$E,$H20)) | D20: =IF($H20="","",T(INDEX('Investment Log'!$G:$G,$H20))) | E20: =IF($H20="","",T(INDEX('Investment Log'!$H:$H,$H20))) | F20: =IF($H20="","",SUM($C$8:$C20)) | H20: =IFERROR(MATCH("Fixed Deposit|"&13,'Investment Log'!$M$8:$M$500,0)+7,"")
A21: =IF($H21="","",INDEX('Investment Log'!$B:$B,$H21)) | B21: =IF($H21="","",T(INDEX('Investment Log'!$D:$D,$H21))) | C21: =IF($H21="","",INDEX('Investment Log'!$E:$E,$H21)) | D21: =IF($H21="","",T(INDEX('Investment Log'!$G:$G,$H21))) | E21: =IF($H21="","",T(INDEX('Investment Log'!$H:$H,$H21))) | F21: =IF($H21="","",SUM($C$8:$C21)) | H21: =IFERROR(MATCH("Fixed Deposit|"&14,'Investment Log'!$M$8:$M$500,0)+7,"")
A22: =IF($H22="","",INDEX('Investment Log'!$B:$B,$H22)) | B22: =IF($H22="","",T(INDEX('Investment Log'!$D:$D,$H22))) | C22: =IF($H22="","",INDEX('Investment Log'!$E:$E,$H22)) | D22: =IF($H22="","",T(INDEX('Investment Log'!$G:$G,$H22))) | E22: =IF($H22="","",T(INDEX('Investment Log'!$H:$H,$H22))) | F22: =IF($H22="","",SUM($C$8:$C22)) | H22: =IFERROR(MATCH("Fixed Deposit|"&15,'Investment Log'!$M$8:$M$500,0)+7,"")
A23: =IF($H23="","",INDEX('Investment Log'!$B:$B,$H23)) | B23: =IF($H23="","",T(INDEX('Investment Log'!$D:$D,$H23))) | C23: =IF($H23="","",INDEX('Investment Log'!$E:$E,$H23)) | D23: =IF($H23="","",T(INDEX('Investment Log'!$G:$G,$H23))) | E23: =IF($H23="","",T(INDEX('Investment Log'!$H:$H,$H23))) | F23: =IF($H23="","",SUM($C$8:$C23)) | H23: =IFERROR(MATCH("Fixed Deposit|"&16,'Investment Log'!$M$8:$M$500,0)+7,"")
A24: =IF($H24="","",INDEX('Investment Log'!$B:$B,$H24)) | B24: =IF($H24="","",T(INDEX('Investment Log'!$D:$D,$H24))) | C24: =IF($H24="","",INDEX('Investment Log'!$E:$E,$H24)) | D24: =IF($H24="","",T(INDEX('Investment Log'!$G:$G,$H24))) | E24: =IF($H24="","",T(INDEX('Investment Log'!$H:$H,$H24))) | F24: =IF($H24="","",SUM($C$8:$C24)) | H24: =IFERROR(MATCH("Fixed Deposit|"&17,'Investment Log'!$M$8:$M$500,0)+7,"")
A25: =IF($H25="","",INDEX('Investment Log'!$B:$B,$H25)) | B25: =IF($H25="","",T(INDEX('Investment Log'!$D:$D,$H25))) | C25: =IF($H25="","",INDEX('Investment Log'!$E:$E,$H25)) | D25: =IF($H25="","",T(INDEX('Investment Log'!$G:$G,$H25))) | E25: =IF($H25="","",T(INDEX('Investment Log'!$H:$H,$H25))) | F25: =IF($H25="","",SUM($C$8:$C25)) | H25: =IFERROR(MATCH("Fixed Deposit|"&18,'Investment Log'!$M$8:$M$500,0)+7,"")
A26: =IF($H26="","",INDEX('Investment Log'!$B:$B,$H26)) | B26: =IF($H26="","",T(INDEX('Investment Log'!$D:$D,$H26))) | C26: =IF($H26="","",INDEX('Investment Log'!$E:$E,$H26)) | D26: =IF($H26="","",T(INDEX('Investment Log'!$G:$G,$H26))) | E26: =IF($H26="","",T(INDEX('Investment Log'!$H:$H,$H26))) | F26: =IF($H26="","",SUM($C$8:$C26)) | H26: =IFERROR(MATCH("Fixed Deposit|"&19,'Investment Log'!$M$8:$M$500,0)+7,"")
A27: =IF($H27="","",INDEX('Investment Log'!$B:$B,$H27)) | B27: =IF($H27="","",T(INDEX('Investment Log'!$D:$D,$H27))) | C27: =IF($H27="","",INDEX('Investment Log'!$E:$E,$H27)) | D27: =IF($H27="","",T(INDEX('Investment Log'!$G:$G,$H27))) | E27: =IF($H27="","",T(INDEX('Investment Log'!$H:$H,$H27))) | F27: =IF($H27="","",SUM($C$8:$C27)) | H27: =IFERROR(MATCH("Fixed Deposit|"&20,'Investment Log'!$M$8:$M$500,0)+7,"")
A28: =IF($H28="","",INDEX('Investment Log'!$B:$B,$H28)) | B28: =IF($H28="","",T(INDEX('Investment Log'!$D:$D,$H28))) | C28: =IF($H28="","",INDEX('Investment Log'!$E:$E,$H28)) | D28: =IF($H28="","",T(INDEX('Investment Log'!$G:$G,$H28))) | E28: =IF($H28="","",T(INDEX('Investment Log'!$H:$H,$H28))) | F28: =IF($H28="","",SUM($C$8:$C28)) | H28: =IFERROR(MATCH("Fixed Deposit|"&21,'Investment Log'!$M$8:$M$500,0)+7,"")
A29: =IF($H29="","",INDEX('Investment Log'!$B:$B,$H29)) | B29: =IF($H29="","",T(INDEX('Investment Log'!$D:$D,$H29))) | C29: =IF($H29="","",INDEX('Investment Log'!$E:$E,$H29)) | D29: =IF($H29="","",T(INDEX('Investment Log'!$G:$G,$H29))) | E29: =IF($H29="","",T(INDEX('Investment Log'!$H:$H,$H29))) | F29: =IF($H29="","",SUM($C$8:$C29)) | H29: =IFERROR(MATCH("Fixed Deposit|"&22,'Investment Log'!$M$8:$M$500,0)+7,"")
A30: =IF($H30="","",INDEX('Investment Log'!$B:$B,$H30)) | B30: =IF($H30="","",T(INDEX('Investment Log'!$D:$D,$H30))) | C30: =IF($H30="","",INDEX('Investment Log'!$E:$E,$H30)) | D30: =IF($H30="","",T(INDEX('Investment Log'!$G:$G,$H30))) | E30: =IF($H30="","",T(INDEX('Investment Log'!$H:$H,$H30))) | F30: =IF($H30="","",SUM($C$8:$C30)) | H30: =IFERROR(MATCH("Fixed Deposit|"&23,'Investment Log'!$M$8:$M$500,0)+7,"")
A31: =IF($H31="","",INDEX('Investment Log'!$B:$B,$H31)) | B31: =IF($H31="","",T(INDEX('Investment Log'!$D:$D,$H31))) | C31: =IF($H31="","",INDEX('Investment Log'!$E:$E,$H31)) | D31: =IF($H31="","",T(INDEX('Investment Log'!$G:$G,$H31))) | E31: =IF($H31="","",T(INDEX('Investment Log'!$H:$H,$H31))) | F31: =IF($H31="","",SUM($C$8:$C31)) | H31: =IFERROR(MATCH("Fixed Deposit|"&24,'Investment Log'!$M$8:$M$500,0)+7,"")
A32: =IF($H32="","",INDEX('Investment Log'!$B:$B,$H32)) | B32: =IF($H32="","",T(INDEX('Investment Log'!$D:$D,$H32))) | C32: =IF($H32="","",INDEX('Investment Log'!$E:$E,$H32)) | D32: =IF($H32="","",T(INDEX('Investment Log'!$G:$G,$H32))) | E32: =IF($H32="","",T(INDEX('Investment Log'!$H:$H,$H32))) | F32: =IF($H32="","",SUM($C$8:$C32)) | H32: =IFERROR(MATCH("Fixed Deposit|"&25,'Investment Log'!$M$8:$M$500,0)+7,"")
A33: =IF($H33="","",INDEX('Investment Log'!$B:$B,$H33)) | B33: =IF($H33="","",T(INDEX('Investment Log'!$D:$D,$H33))) | C33: =IF($H33="","",INDEX('Investment Log'!$E:$E,$H33)) | D33: =IF($H33="","",T(INDEX('Investment Log'!$G:$G,$H33))) | E33: =IF($H33="","",T(INDEX('Investment Log'!$H:$H,$H33))) | F33: =IF($H33="","",SUM($C$8:$C33)) | H33: =IFERROR(MATCH("Fixed Deposit|"&26,'Investment Log'!$M$8:$M$500,0)+7,"")
A34: =IF($H34="","",INDEX('Investment Log'!$B:$B,$H34)) | B34: =IF($H34="","",T(INDEX('Investment Log'!$D:$D,$H34))) | C34: =IF($H34="","",INDEX('Investment Log'!$E:$E,$H34)) | D34: =IF($H34="","",T(INDEX('Investment Log'!$G:$G,$H34))) | E34: =IF($H34="","",T(INDEX('Investment Log'!$H:$H,$H34))) | F34: =IF($H34="","",SUM($C$8:$C34)) | H34: =IFERROR(MATCH("Fixed Deposit|"&27,'Investment Log'!$M$8:$M$500,0)+7,"")
A35: =IF($H35="","",INDEX('Investment Log'!$B:$B,$H35)) | B35: =IF($H35="","",T(INDEX('Investment Log'!$D:$D,$H35))) | C35: =IF($H35="","",INDEX('Investment Log'!$E:$E,$H35)) | D35: =IF($H35="","",T(INDEX('Investment Log'!$G:$G,$H35))) | E35: =IF($H35="","",T(INDEX('Investment Log'!$H:$H,$H35))) | F35: =IF($H35="","",SUM($C$8:$C35)) | H35: =IFERROR(MATCH("Fixed Deposit|"&28,'Investment Log'!$M$8:$M$500,0)+7,"")
A36: =IF($H36="","",INDEX('Investment Log'!$B:$B,$H36)) | B36: =IF($H36="","",T(INDEX('Investment Log'!$D:$D,$H36))) | C36: =IF($H36="","",INDEX('Investment Log'!$E:$E,$H36)) | D36: =IF($H36="","",T(INDEX('Investment Log'!$G:$G,$H36))) | E36: =IF($H36="","",T(INDEX('Investment Log'!$H:$H,$H36))) | F36: =IF($H36="","",SUM($C$8:$C36)) | H36: =IFERROR(MATCH("Fixed Deposit|"&29,'Investment Log'!$M$8:$M$500,0)+7,"")
A37: =IF($H37="","",INDEX('Investment Log'!$B:$B,$H37)) | B37: =IF($H37="","",T(INDEX('Investment Log'!$D:$D,$H37))) | C37: =IF($H37="","",INDEX('Investment Log'!$E:$E,$H37)) | D37: =IF($H37="","",T(INDEX('Investment Log'!$G:$G,$H37))) | E37: =IF($H37="","",T(INDEX('Investment Log'!$H:$H,$H37))) | F37: =IF($H37="","",SUM($C$8:$C37)) | H37: =IFERROR(MATCH("Fixed Deposit|"&30,'Investment Log'!$M$8:$M$500,0)+7,"")
A38: =IF($H38="","",INDEX('Investment Log'!$B:$B,$H38)) | B38: =IF($H38="","",T(INDEX('Investment Log'!$D:$D,$H38))) | C38: =IF($H38="","",INDEX('Investment Log'!$E:$E,$H38)) | D38: =IF($H38="","",T(INDEX('Investment Log'!$G:$G,$H38))) | E38: =IF($H38="","",T(INDEX('Investment Log'!$H:$H,$H38))) | F38: =IF($H38="","",SUM($C$8:$C38)) | H38: =IFERROR(MATCH("Fixed Deposit|"&31,'Investment Log'!$M$8:$M$500,0)+7,"")
A39: =IF($H39="","",INDEX('Investment Log'!$B:$B,$H39)) | B39: =IF($H39="","",T(INDEX('Investment Log'!$D:$D,$H39))) | C39: =IF($H39="","",INDEX('Investment Log'!$E:$E,$H39)) | D39: =IF($H39="","",T(INDEX('Investment Log'!$G:$G,$H39))) | E39: =IF($H39="","",T(INDEX('Investment Log'!$H:$H,$H39))) | F39: =IF($H39="","",SUM($C$8:$C39)) | H39: =IFERROR(MATCH("Fixed Deposit|"&32,'Investment Log'!$M$8:$M$500,0)+7,"")
A40: =IF($H40="","",INDEX('Investment Log'!$B:$B,$H40)) | B40: =IF($H40="","",T(INDEX('Investment Log'!$D:$D,$H40))) | C40: =IF($H40="","",INDEX('Investment Log'!$E:$E,$H40)) | D40: =IF($H40="","",T(INDEX('Investment Log'!$G:$G,$H40))) | E40: =IF($H40="","",T(INDEX('Investment Log'!$H:$H,$H40))) | F40: =IF($H40="","",SUM($C$8:$C40)) | H40: =IFERROR(MATCH("Fixed Deposit|"&33,'Investment Log'!$M$8:$M$500,0)+7,"")
A41: =IF($H41="","",INDEX('Investment Log'!$B:$B,$H41)) | B41: =IF($H41="","",T(INDEX('Investment Log'!$D:$D,$H41))) | C41: =IF($H41="","",INDEX('Investment Log'!$E:$E,$H41)) | D41: =IF($H41="","",T(INDEX('Investment Log'!$G:$G,$H41))) | E41: =IF($H41="","",T(INDEX('Investment Log'!$H:$H,$H41))) | F41: =IF($H41="","",SUM($C$8:$C41)) | H41: =IFERROR(MATCH("Fixed Deposit|"&34,'Investment Log'!$M$8:$M$500,0)+7,"")
A42: =IF($H42="","",INDEX('Investment Log'!$B:$B,$H42)) | B42: =IF($H42="","",T(INDEX('Investment Log'!$D:$D,$H42))) | C42: =IF($H42="","",INDEX('Investment Log'!$E:$E,$H42)) | D42: =IF($H42="","",T(INDEX('Investment Log'!$G:$G,$H42))) | E42: =IF($H42="","",T(INDEX('Investment Log'!$H:$H,$H42))) | F42: =IF($H42="","",SUM($C$8:$C42)) | H42: =IFERROR(MATCH("Fixed Deposit|"&35,'Investment Log'!$M$8:$M$500,0)+7,"")
...

Sheet Mutual Funds
A1: MUTUAL FUNDS
A2: Auto-updates from the Investment Log — do not type here.
A4: TOTAL INVESTED (₹) | B4: RECORDS
A5: =SUMIF('Investment Log'!$C$8:$C$500,"Mutual Funds",'Investment Log'!$E$8:$E$500) -> 200000 | B5: =COUNTIF('Investment Log'!$C$8:$C$500,"Mutual Funds") -> 1
A7: Date | B7: Description / Name | C7: Amount Invested (₹) | D7: Platform / Account | E7: Notes | F7: Running Total (₹)
A8: =IF($H8="","",INDEX('Investment Log'!$B:$B,$H8)) -> 46054 | B8: =IF($H8="","",T(INDEX('Investment Log'!$D:$D,$H8))) -> Kuvera portfolio | C8: =IF($H8="","",INDEX('Investment Log'!$E:$E,$H8)) -> 200000 | D8: =IF($H8="","",T(INDEX('Investment Log'!$G:$G,$H8))) -> Kuvera app | E8: =IF($H8="","",T(INDEX('Investment Log'!$H:$H,$H8))) -> Day not specified. | F8: =IF($H8="","",SUM($C$8:$C8)) -> 200000 | H8: =IFERROR(MATCH("Mutual Funds|"&1,'Investment Log'!$M$8:$M$500,0)+7,"") -> 12
A9: =IF($H9="","",INDEX('Investment Log'!$B:$B,$H9)) | B9: =IF($H9="","",T(INDEX('Investment Log'!$D:$D,$H9))) | C9: =IF($H9="","",INDEX('Investment Log'!$E:$E,$H9)) | D9: =IF($H9="","",T(INDEX('Investment Log'!$G:$G,$H9))) | E9: =IF($H9="","",T(INDEX('Investment Log'!$H:$H,$H9))) | F9: =IF($H9="","",SUM($C$8:$C9)) | H9: =IFERROR(MATCH("Mutual Funds|"&2,'Investment Log'!$M$8:$M$500,0)+7,"")
A10: =IF($H10="","",INDEX('Investment Log'!$B:$B,$H10)) | B10: =IF($H10="","",T(INDEX('Investment Log'!$D:$D,$H10))) | C10: =IF($H10="","",INDEX('Investment Log'!$E:$E,$H10)) | D10: =IF($H10="","",T(INDEX('Investment Log'!$G:$G,$H10))) | E10: =IF($H10="","",T(INDEX('Investment Log'!$H:$H,$H10))) | F10: =IF($H10="","",SUM($C$8:$C10)) | H10: =IFERROR(MATCH("Mutual Funds|"&3,'Investment Log'!$M$8:$M$500,0)+7,"")
A11: =IF($H11="","",INDEX('Investment Log'!$B:$B,$H11)) | B11: =IF($H11="","",T(INDEX('Investment Log'!$D:$D,$H11))) | C11: =IF($H11="","",INDEX('Investment Log'!$E:$E,$H11)) | D11: =IF($H11="","",T(INDEX('Investment Log'!$G:$G,$H11))) | E11: =IF($H11="","",T(INDEX('Investment Log'!$H:$H,$H11))) | F11: =IF($H11="","",SUM($C$8:$C11)) | H11: =IFERROR(MATCH("Mutual Funds|"&4,'Investment Log'!$M$8:$M$500,0)+7,"")
A12: =IF($H12="","",INDEX('Investment Log'!$B:$B,$H12)) | B12: =IF($H12="","",T(INDEX('Investment Log'!$D:$D,$H12))) | C12: =IF($H12="","",INDEX('Investment Log'!$E:$E,$H12)) | D12: =IF($H12="","",T(INDEX('Investment Log'!$G:$G,$H12))) | E12: =IF($H12="","",T(INDEX('Investment Log'!$H:$H,$H12))) | F12: =IF($H12="","",SUM($C$8:$C12)) | H12: =IFERROR(MATCH("Mutual Funds|"&5,'Investment Log'!$M$8:$M$500,0)+7,"")
A13: =IF($H13="","",INDEX('Investment Log'!$B:$B,$H13)) | B13: =IF($H13="","",T(INDEX('Investment Log'!$D:$D,$H13))) | C13: =IF($H13="","",INDEX('Investment Log'!$E:$E,$H13)) | D13: =IF($H13="","",T(INDEX('Investment Log'!$G:$G,$H13))) | E13: =IF($H13="","",T(INDEX('Investment Log'!$H:$H,$H13))) | F13: =IF($H13="","",SUM($C$8:$C13)) | H13: =IFERROR(MATCH("Mutual Funds|"&6,'Investment Log'!$M$8:$M$500,0)+7,"")
A14: =IF($H14="","",INDEX('Investment Log'!$B:$B,$H14)) | B14: =IF($H14="","",T(INDEX('Investment Log'!$D:$D,$H14))) | C14: =IF($H14="","",INDEX('Investment Log'!$E:$E,$H14)) | D14: =IF($H14="","",T(INDEX('Investment Log'!$G:$G,$H14))) | E14: =IF($H14="","",T(INDEX('Investment Log'!$H:$H,$H14))) | F14: =IF($H14="","",SUM($C$8:$C14)) | H14: =IFERROR(MATCH("Mutual Funds|"&7,'Investment Log'!$M$8:$M$500,0)+7,"")
A15: =IF($H15="","",INDEX('Investment Log'!$B:$B,$H15)) | B15: =IF($H15="","",T(INDEX('Investment Log'!$D:$D,$H15))) | C15: =IF($H15="","",INDEX('Investment Log'!$E:$E,$H15)) | D15: =IF($H15="","",T(INDEX('Investment Log'!$G:$G,$H15))) | E15: =IF($H15="","",T(INDEX('Investment Log'!$H:$H,$H15))) | F15: =IF($H15="","",SUM($C$8:$C15)) | H15: =IFERROR(MATCH("Mutual Funds|"&8,'Investment Log'!$M$8:$M$500,0)+7,"")
A16: =IF($H16="","",INDEX('Investment Log'!$B:$B,$H16)) | B16: =IF($H16="","",T(INDEX('Investment Log'!$D:$D,$H16))) | C16: =IF($H16="","",INDEX('Investment Log'!$E:$E,$H16)) | D16: =IF($H16="","",T(INDEX('Investment Log'!$G:$G,$H16))) | E16: =IF($H16="","",T(INDEX('Investment Log'!$H:$H,$H16))) | F16: =IF($H16="","",SUM($C$8:$C16)) | H16: =IFERROR(MATCH("Mutual Funds|"&9,'Investment Log'!$M$8:$M$500,0)+7,"")
A17: =IF($H17="","",INDEX('Investment Log'!$B:$B,$H17)) | B17: =IF($H17="","",T(INDEX('Investment Log'!$D:$D,$H17))) | C17: =IF($H17="","",INDEX('Investment Log'!$E:$E,$H17)) | D17: =IF($H17="","",T(INDEX('Investment Log'!$G:$G,$H17))) | E17: =IF($H17="","",T(INDEX('Investment Log'!$H:$H,$H17))) | F17: =IF($H17="","",SUM($C$8:$C17)) | H17: =IFERROR(MATCH("Mutual Funds|"&10,'Investment Log'!$M$8:$M$500,0)+7,"")
A18: =IF($H18="","",INDEX('Investment Log'!$B:$B,$H18)) | B18: =IF($H18="","",T(INDEX('Investment Log'!$D:$D,$H18))) | C18: =IF($H18="","",INDEX('Investment Log'!$E:$E,$H18)) | D18: =IF($H18="","",T(INDEX('Investment Log'!$G:$G,$H18))) | E18: =IF($H18="","",T(INDEX('Investment Log'!$H:$H,$H18))) | F18: =IF($H18="","",SUM($C$8:$C18)) | H18: =IFERROR(MATCH("Mutual Funds|"&11,'Investment Log'!$M$8:$M$500,0)+7,"")
A19: =IF($H19="","",INDEX('Investment Log'!$B:$B,$H19)) | B19: =IF($H19="","",T(INDEX('Investment Log'!$D:$D,$H19))) | C19: =IF($H19="","",INDEX('Investment Log'!$E:$E,$H19)) | D19: =IF($H19="","",T(INDEX('Investment Log'!$G:$G,$H19))) | E19: =IF($H19="","",T(INDEX('Investment Log'!$H:$H,$H19))) | F19: =IF($H19="","",SUM($C$8:$C19)) | H19: =IFERROR(MATCH("Mutual Funds|"&12,'Investment Log'!$M$8:$M$500,0)+7,"")
A20: =IF($H20="","",INDEX('Investment Log'!$B:$B,$H20)) | B20: =IF($H20="","",T(INDEX('Investment Log'!$D:$D,$H20))) | C20: =IF($H20="","",INDEX('Investment Log'!$E:$E,$H20)) | D20: =IF($H20="","",T(INDEX('Investment Log'!$G:$G,$H20))) | E20: =IF($H20="","",T(INDEX('Investment Log'!$H:$H,$H20))) | F20: =IF($H20="","",SUM($C$8:$C20)) | H20: =IFERROR(MATCH("Mutual Funds|"&13,'Investment Log'!$M$8:$M$500,0)+7,"")
A21: =IF($H21="","",INDEX('Investment Log'!$B:$B,$H21)) | B21: =IF($H21="","",T(INDEX('Investment Log'!$D:$D,$H21))) | C21: =IF($H21="","",INDEX('Investment Log'!$E:$E,$H21)) | D21: =IF($H21="","",T(INDEX('Investment Log'!$G:$G,$H21))) | E21: =IF($H21="","",T(INDEX('Investment Log'!$H:$H,$H21))) | F21: =IF($H21="","",SUM($C$8:$C21)) | H21: =IFERROR(MATCH("Mutual Funds|"&14,'Investment Log'!$M$8:$M$500,0)+7,"")
A22: =IF($H22="","",INDEX('Investment Log'!$B:$B,$H22)) | B22: =IF($H22="","",T(INDEX('Investment Log'!$D:$D,$H22))) | C22: =IF($H22="","",INDEX('Investment Log'!$E:$E,$H22)) | D22: =IF($H22="","",T(INDEX('Investment Log'!$G:$G,$H22))) | E22: =IF($H22="","",T(INDEX('Investment Log'!$H:$H,$H22))) | F22: =IF($H22="","",SUM($C$8:$C22)) | H22: =IFERROR(MATCH("Mutual Funds|"&15,'Investment Log'!$M$8:$M$500,0)+7,"")
A23: =IF($H23="","",INDEX('Investment Log'!$B:$B,$H23)) | B23: =IF($H23="","",T(INDEX('Investment Log'!$D:$D,$H23))) | C23: =IF($H23="","",INDEX('Investment Log'!$E:$E,$H23)) | D23: =IF($H23="","",T(INDEX('Investment Log'!$G:$G,$H23))) | E23: =IF($H23="","",T(INDEX('Investment Log'!$H:$H,$H23))) | F23: =IF($H23="","",SUM($C$8:$C23)) | H23: =IFERROR(MATCH("Mutual Funds|"&16,'Investment Log'!$M$8:$M$500,0)+7,"")
A24: =IF($H24="","",INDEX('Investment Log'!$B:$B,$H24)) | B24: =IF($H24="","",T(INDEX('Investment Log'!$D:$D,$H24))) | C24: =IF($H24="","",INDEX('Investment Log'!$E:$E,$H24)) | D24: =IF($H24="","",T(INDEX('Investment Log'!$G:$G,$H24))) | E24: =IF($H24="","",T(INDEX('Investment Log'!$H:$H,$H24))) | F24: =IF($H24="","",SUM($C$8:$C24)) | H24: =IFERROR(MATCH("Mutual Funds|"&17,'Investment Log'!$M$8:$M$500,0)+7,"")
A25: =IF($H25="","",INDEX('Investment Log'!$B:$B,$H25)) | B25: =IF($H25="","",T(INDEX('Investment Log'!$D:$D,$H25))) | C25: =IF($H25="","",INDEX('Investment Log'!$E:$E,$H25)) | D25: =IF($H25="","",T(INDEX('Investment Log'!$G:$G,$H25))) | E25: =IF($H25="","",T(INDEX('Investment Log'!$H:$H,$H25))) | F25: =IF($H25="","",SUM($C$8:$C25)) | H25: =IFERROR(MATCH("Mutual Funds|"&18,'Investment Log'!$M$8:$M$500,0)+7,"")
A26: =IF($H26="","",INDEX('Investment Log'!$B:$B,$H26)) | B26: =IF($H26="","",T(INDEX('Investment Log'!$D:$D,$H26))) | C26: =IF($H26="","",INDEX('Investment Log'!$E:$E,$H26)) | D26: =IF($H26="","",T(INDEX('Investment Log'!$G:$G,$H26))) | E26: =IF($H26="","",T(INDEX('Investment Log'!$H:$H,$H26))) | F26: =IF($H26="","",SUM($C$8:$C26)) | H26: =IFERROR(MATCH("Mutual Funds|"&19,'Investment Log'!$M$8:$M$500,0)+7,"")
A27: =IF($H27="","",INDEX('Investment Log'!$B:$B,$H27)) | B27: =IF($H27="","",T(INDEX('Investment Log'!$D:$D,$H27))) | C27: =IF($H27="","",INDEX('Investment Log'!$E:$E,$H27)) | D27: =IF($H27="","",T(INDEX('Investment Log'!$G:$G,$H27))) | E27: =IF($H27="","",T(INDEX('Investment Log'!$H:$H,$H27))) | F27: =IF($H27="","",SUM($C$8:$C27)) | H27: =IFERROR(MATCH("Mutual Funds|"&20,'Investment Log'!$M$8:$M$500,0)+7,"")
